Workbook

Sheet Overview
B3: Summary | C3: EUR iBoxx IG proxy | D3: USD JULI-ex EM proxy
B4: # of Bonds | C4: 66 | D4: 64
B5: # of Issuers | C5: 63 | D5: 63
B6: Notional (native CCY mm) | C6: 99.789 | D6: 90.197
B7: Notional (EUR mm equiv) | C7: 99.937689 | D7: 78.55513
B8: Market Value (EUR mm equiv) | C8: 99.937689 | D8: 75.019719
B9: Average Rating | C9: A- | D9: A-
B10: Px | C10: 100.149 | D10: 95.499453
B11: MV Spread | C11: 82.112132 | D11: 84.601402
B12: MV-Duration Spread | C12: 92.729835 | D12: 98.014102
B13: Yield (FX adj) | C13: 3.0678137 | D13: 2.9878583
B14: Duration | C14: 4.4586971 | D14: 6.5086006
B15: Average Maturity | C15: 5.4839021 | D15: 10.292732
B17: Rating | C17: EUR iBoxx IG proxy | D17: USD JULI-ex EM proxy
B18: AAA | C18: 0 | D18: 0.017336488
B19: AA+ | C19: 0 | D19: 0
B20: AA | C20: 0.004927027 | D20: 0
B21: AA- | C21: 0.061550988 | D21: 0.043448621
B22: A+ | C22: 0.1204611 | D22: 0.11118159
B23: A | C23: 0.11397341 | D23: 0.13020895
B24: A- | C24: 0.21677766 | D24: 0.17508247
B25: BBB+ | C25: 0.24149504 | D25: 0.20705372
B26: BBB | C26: 0.1574199 | D26: 0.20861904
B27: BBB- | C27: 0.083394875 | D27: 0.10706913
B28: BB+ | C28: 0 | D28: 0
B29: BB | C29: 0 | D29: 0
B30: None | C30: 0 | D30: 0
B32: Sector | C32: EUR iBoxx IG proxy | D32: USD JULI-ex EM proxy
B33: Financial | C33: 0.43341829 | D33: 0.3343961
B34: Communications | C34: 0.059904467 | D34: 0.10604684
B35: Consumer, Non-cyclical | C35: 0.15713596 | D35: 0.19198542
B36: Energy | C36: 0.023423667 | D36: 0.065794413
B37: Consumer, Cyclical | C37: 0.077900692 | D37: 0.077567207
B38: Technology | C38: 0.020243647 | D38: 0.086819541
B39: Basic Materials | C39: 0.035879054 | D39: 0.017370802
B40: Industrial | C40: 0.074674301 | D40: 0.047091783
B41: Utilities | C41: 0.11741992 | D41: 0.072927897
B43: Maturity Bucket | C43: EUR iBoxx IG proxy | D43: USD JULI-ex EM proxy
B44: <1yr | C44: 0.0049987208 | D44: 0.012347625
B45: 1-3yrs | C45: 0.30067325 | D45: 0.23229654
...

Sheet EUR iBoxx IG proxy
A1: ISIN | B1: CUSIP | C1: Bond | D1: Notional | E1: Ticker | F1: Issuer | G1: Sector | H1: Group | I1: Moody | J1: S&P | K1: Fitch | L1: Rating | M1: Payment Rank | N1: Duration | O1: Quote Type | P1: JPM Price | Q1: JPM Spread | R1: JPM Yield | S1: JPM MV | T1: Years to Maturity | U1: Maturity Bucket | V1: Country | W1: Amount Outstanding | X1: Ordinal Rating
A2: BE6285455497 | C2: ABIBB 2 03/17/28 | D2: 658000 | E2: ABIBB | F2: Anheuser-Busch InBev SA/NV | G2: Consumer, Non-cyclical | H2: Beverages | I2: A3 | J2: A- | K2: WD | L2: A- | M2: Senior Unsecured | N2: 2.2428929 | O2: Spread | P2: 99.027764 | Q2: 44.04 | R2: 2.4271 | S2: 651602.69 | T2: 2.3643836 | U2: 1-3yrs | V2: BE | W2: 2911466000 | X2: 7
A3: XS3083189319 | C3: ABNANV 2 3/4 06/04/29 | D3: 2000000 | E3: ABNANV | F3: ABN AMRO Bank NV | G3: Financial | H3: Banks | I3: Aa3 | J3: A | K3: A+ | L3: A+ | M3: Senior Unsecured | N3: 3.3279205 | O3: Spread | P3: 100.4117 | Q3: 52.318 | R3: 2.62518 | S3: 2008234.1 | T3: 3.5808219 | U3: 3-5yrs | V3: NL | W3: 1000000000 | X3: 5
A4: FR0014012B88 | C4: ACFP 3 5/8 09/03/32 | D4: 1100000 | E4: ACFP | F4: Accor SA | G4: Consumer, Cyclical | H4: Lodging | I4: N/A | J4: BBB- | K4: BBB- | L4: BBB- | M4: Senior Unsecured | N4: 5.9159303 | O4: Spread | P4: 100.11258 | Q4: 121.102 | R4: 3.60452 | S4: 1101238.3 | T4: 6.8328767 | U4: 5-7yrs | V4: FR | W4: 500000000 | X4: 10
A5: FR0013505633 | C5: ADPFP 2 3/4 04/02/30 | D5: 600000 | E5: ADPFP | F5: Aeroports de Paris SA | G5: Industrial | H5: Engineering&Construction | I5: N/A | J5: A- | K5: BBB+ | L5: BBB+ | M5: Senior Unsecured | N5: 4.0181923 | O5: Spread | P5: 99.065383 | Q5: 81.249 | R5: 2.97739 | S5: 594392.3 | T5: 4.4082192 | U5: 3-5yrs | V5: FR | W5: 1500000000 | X5: 8
A6: XS3215529192 | C6: ASNBNK 3 3/8 10/27/32 | D6: 2000000 | E6: ASNBNK | F6: ASN Bank NV | G6: Financial | H6: Banks | I6: Baa1 | J6: N/A | K6: A- | L6: BBB+ | M6: Senior Unsecured | N6: 6.1055068 | O6: Spread | P6: 99.365066 | Q6: 108.538 | R6: 3.47888 | S6: 1987301.3 | T6: 6.9808219 | U6: 5-7yrs | V6: NL | W6: 500000000 | X6: 8
A7: XS3135127119 | C7: ATH 2 7/8 07/21/28 | D7: 1138000 | E7: ATH | F7: Athene Global Funding | G7: Financial | H7: Insurance | I7: A1 | J7: A+ | K7: A+ | L7: A+ | M7: Senior Unsecured | N7: 2.5442377 | O7: Spread | P7: 99.874668 | Q7: 93.397 | R7: 2.92067 | S7: 1136573.7 | T7: 2.709589 | U7: 1-3yrs | V7: US | W7: 700000000 | X7: 5
A8: FR001400F6E7 | C8: AYVFP 4 1/4 01/18/27 | D8: 1800000 | E8: AYVFP | F8: Ayvens SA | G8: Consumer, Non-cyclical | H8: Commercial Services | I8: A1 | J8: A- | K8: A- | L8: A- | M8: Senior Unsecured | N8: 1.1293946 | O8: Spread | P8: 102.07977 | Q8: 50.13 | R8: 2.4589 | S8: 1837435.8 | T8: 1.2027397 | U8: 1-3yrs | V8: FR | W8: 750000000 | X8: 7
A9: XS3217583049 | C9: BAC 2.984 10/30/31 | D9: 2000000 | E9: BAC | F9: Bank of America Corp | G9: Financial | H9: Banks | I9: A1 | J9: A- | K9: AA- | L9: A+ | M9: Senior Unsecured | N9: 4.5548264 | O9: Spread | P9: 99.49661 | Q9: 83.995 | R9: 3.09445 | S9: 1989932.2 | T9: 5.9863014 | U9: 5-7yrs | V9: US | W9: 1750000000 | X9: 5
A10: XS3075491152 | C10: BMW 2 5/8 05/20/28 | D10: 1582000 | E10: BMW | F10: BMW Finance NV | G10: Consumer, Cyclical | H10: Auto Manufacturers | I10: A2 | J10: A | K10: N/A | L10: A | M10: Senior Unsecured | N10: 2.3957166 | O10: Spread | P10: 100.29841 | Q10: 51.186 | R10: 2.49856 | S10: 1586720.9 | T10: 2.539726 | U10: 1-3yrs | V10: DE | W10: 1000000000 | X10: 6
A11: FR0013484458 | C11: BNP 0 1/2 02/19/28 | D11: 2000000 | E11: BNP | F11: BNP Paribas SA | G11: Financial | H11: Banks | I11: Baa1 | J11: A- | K11: A+ | L11: A- | M11: Senior Unsecured | N11: 1.2473208 | O11: Spread | P11: 97.368355 | Q11: 66.523 | R11: 2.60813 | S11: 1947367.1 | T11: 2.290411 | U11: 1-3yrs | V11: FR | W11: 1250000000 | X11: 7
A12: XS3084359036 | C12: BRITEL 3 3/4 01/03/35 | D12: 1324000 | E12: BRITEL | F12: British Telecommunications PLC | G12: Communications | H12: Telecommunications | I12: Baa2 | J12: BBB | K12: BBB | L12: BBB | M12: Senior Unsecured | N12: 7.3410382 | O12: Spread | P12: 100.50499 | Q12: 106.856 | R12: 3.68366 | S12: 1330686 | T12: 9.1671233 | U12: 7-10yrs | V12: GB | W12: 700000000 | X12: 9
A13: XS1200679071 | B13: 084670BN7 | C13: BRK 1 1/8 03/16/27 | D13: 500000 | E13: BRK | F13: Berkshire Hathaway Inc | G13: Financial | H13: Insurance | I13: Aa2 | J13: AA | K13: A+ | L13: AA | M13: Senior Unsecured | N13: 1.312298 | O13: Spread | P13: 98.479138 | Q13: 33.376 | R13: 2.27666 | S13: 492395.69 | T13: 1.3589041 | U13: 1-3yrs | V13: US | W13: 1250000000 | X13: 3
A14: XS3214409834 | C14: C 3.493 10/22/34 | D14: 2000000 | E14: C | F14: Citigroup Inc | G14: Financial | H14: Banks | I14: A3 | J14: BBB+ | K14: A | L14: A- | M14: Senior Unsecured | N14: 6.8235849 | O14: Spread | P14: 99.319609 | Q14: 109.316 | R14: 3.59246 | S14: 1986392.2 | T14: 8.9671233 | U14: 7-10yrs | V14: US | W14: 1500000000 | X14: 7
A15: XS2679904768 | C15: CAJAMA 7 1/2 09/14/29 | D15: 1600000 | E15: CAJAMA | F15: Banco de Credito Social Cooperativo SA | G15: Financial | H15: Banks | I15: N/A | J15: BBB- | K15: BBB | L15: BBB- | M15: Senior Unsecured | N15: 2.5865735 | O15: Spread | P15: 112.52444 | Q15: 85.773 | R15: 2.85973 | S15: 1800391.1 | T15: 3.860274 | U15: 3-5yrs | V15: ES | W15: 650000000 | X15: 10
A16: XS3002420498 | C16: CARLB 3 1/4 02/28/32 | D16: 1291000 | E16: CARLB | F16: Carlsberg Breweries A/S | G16: Consumer, Non-cyclical | H16: Beverages | I16: Baa1 | J16: N/A | K16: BBB+ | L16: BBB+ | M16: Senior Unsecured | N16: 5.3049809 | O16: Spread | P16: 100.23397 | Q16: 85.414 | R16: 3.20634 | S16: 1294020.6 | T16: 6.3178082 | U16: 5-7yrs | V16: DK | W16: 1000000000 | X16: 8
A17: XS3151775023 | C17: CAT 2.521 08/22/28 | D17: 1205000 | E17: CAT | F17: Caterpillar Financial Services Corp | G17: Industrial | H17: Machinery-Constr&Mining | I17: A2 | J17: A | K17: A+ | L17: A | M17: Senior Unsecured | N17: 2.6515042 | O17: Spread | P17: 100.23331 | Q17: 42.958 | R17: 2.43158 | S17: 1207811.4 | T17: 2.7972603 | U17: 1-3yrs | V17: US | W17: 600000000 | X17: 6
A18: XS3118936452 | C18: CM 3 1/4 07/16/31 | D18: 2000000 | E18: CM | F18: Canadian Imperial Bank of Commerce | G18: Financial | H18: Banks | I18: A2 | J18: A- | K18: AA- | L18: A | M18: Senior Unsecured | N18: 4.2505854 | O18: Spread | P18: 100.50574 | Q18: 92.233 | R18: 3.12983 | S18: 2010114.8 | T18: 5.6958904 | U18: 5-7yrs | V18: CA | W18: 1250000000 | X18: 6
A19: XS3017991368 | C19: CTPNV 4 1/4 03/10/35 | D19: 1263000 | E19: CTPNV | F19: CTP NV | G19: Financial | H19: Real Estate | I19: Baa3 | J19: BBB | K19: N/A | L19: BBB- | M19: Senior Unsecured | N19: 7.2278275 | O19: Spread | P19: 100.82077 | Q19: 151.863 | R19: 4.13873 | S19: 1273366.3 | T19: 9.3479452 | U19: 7-10yrs | V19: NL | W19: 500000000 | X19: 10
A20: DE000DL19U23 | C20: DB 1 5/8 01/20/27 | D20: 2000000 | E20: DB | F20: Deutsche Bank AG | G20: Financial | H20: Banks | I20: Baa1 | J20: BBB | K20: A- | L20: BBB+ | M20: Senior Unsecured | N20: 1.1577336 | O20: Spread | P20: 98.978786 | Q20: 55.805 | R20: 2.49465 | S20: 1979575.7 | T20: 1.2082192 | U20: 1-3yrs | V20: DE | W20: 1475000000 | X20: 8
A21: DE000A4DFSK4 | C21: DB 2 5/8 08/13/28 | D21: 2000000 | E21: DB | F21: Deutsche Bank AG | G21: Financial | H21: Banks | I21: Baa1 | J21: BBB | K21: A- | L21: BBB+ | M21: Senior Unsecured | N21: 1.692865 | O21: Spread | P21: 99.844919 | Q21: 74.499 | R21: 2.71249 | S21: 1996898.4 | T21: 2.7726027 | U21: 1-3yrs | V21: DE | W21: 1250000000 | X21: 8
A22: XS3198651872 | C22: DGELN 3 1/4 10/03/32 | D22: 2000000 | E22: DGELN | F22: Diageo Finance PLC | G22: Consumer, Non-cyclical | H22: Beverages | I22: A3 | J22: A- | K22: A- | L22: A- | M22: Senior Unsecured | N22: 6.0789842 | O22: Spread | P22: 99.98466 | Q22: 85.828 | R22: 3.25178 | S22: 1999693.2 | T22: 6.9150685 | U22: 5-7yrs | V22: GB | W22: 500000000 | X22: 7
A23: XS2932831923 | C23: DSVDC 3 1/8 11/06/28 | D23: 1236000 | E23: DSVDC | F23: DSV Finance BV | G23: Industrial | H23: Transportation | I23: A3 | J23: A- | K23: N/A | L23: A- | M23: Senior Unsecured | N23: 2.6815507 | O23: Spread | P23: 101.43242 | Q23: 55.038 | R23: 2.59548 | S23: 1253704.8 | T23: 3.0054795 | U23: 1-3yrs | V23: DK | W23: 1000000000 | X23: 7
A24: XS2948768556 | C24: DT 3 1/4 06/04/35 | D24: 2000000 | E24: DT | F24: Deutsche Telekom AG | G24: Communications | H24: Telecommunications | I24: A3 | J24: BBB+ | K24: BBB+ | L24: BBB+ | M24: Senior Unsecured | N24: 8.0047244 | O24: Spread | P24: 99.772829 | Q24: 61.225 | R24: 3.27645 | S24: 1995456.6 | T24: 9.5835616 | U24: 7-10yrs | V24: DE | W24: 850000000 | X24: 8
A25: XS3081821699 | C25: DTRGR 3 11/27/29 | D25: 2000000 | E25: DTRGR | F25: Daimler Truck International Finance BV | G25: Consumer, Cyclical | H25: Auto Manufacturers | I25: A3 | J25: A- | K25: N/A | L25: A- | M25: Senior Unsecured | N25: 3.7196671 | O25: Spread | P25: 100.43091 | Q25: 72.989 | R25: 2.88589 | S25: 2008618.3 | T25: 4.0630137 | U25: 3-5yrs | V25: DE | W25: 650000000 | X25: 7
... A29: XS3201905091 | C29: EUROGR 4.165 10/16/40 | D29: 1900000 | E29: EUROGR | F29: Eurogrid GmbH | G29: Utilities | H29: Electric | I29: N/A | J29: BBB | K29: N/A | L29: BBB | M29: Senior Unsecured | N29: 10.819507 | O29: Spread | P29: 100.78355 | Q29: 113.494 | R29: 4.09334 | S29: 1914887.4 | T29: 14.956164 | U29: 10yrs+ | V29: DE | W29: 600000000 | X29: 9
A30: XS3060660563 | B30: 337735AC8 | C30: FI 4 06/15/36 | D30: 500000 | E30: FI | F30: Fiserv Funding ULC | G30: Consumer, Non-cyclical | H30: Commercial Services | I30: Baa2 | J30: BBB | K30: N/A | L30: BBB | M30: Senior Unsecured | N30: 8.3456173 | O30: Spread | P30: 98.387111 | Q30: 143.778 | R30: 4.18918 | S30: 491935.56 | T30: 10.616438 | U30: 10yrs+ | V30: US | W30: 650000000 | X30: 9
A31: XS3194155563 | C31: GLENLN 3.668 10/06/32 | D31: 500000 | E31: GLENLN | F31: Glencore Capital Finance DAC | G31: Basic Materials | H31: Mining | I31: A3 | J31: BBB+ | K31: N/A | L31: BBB+ | M31: Senior Unsecured | N31: 5.9938938 | O31: Spread | P31: 100.14672 | Q31: 124.924 | R31: 3.64274 | S31: 500733.58 | T31: 6.9232877 | U31: 5-7yrs | V31: AU | W31: 500000000 | X31: 8
A32: XS2908095172 | C32: HBRLN 4.357 10/03/32 | D32: 500000 | E32: HBRLN | F32: Wintershall Dea Finance BV | G32: Energy | H32: Oil&Gas | I32: Baa2 | J32: BBB- | K32: BBB- | L32: BBB- | M32: Senior Unsecured | N32: 5.6667051 | O32: Spread | P32: 101.55973 | Q32: 169.191 | R32: 4.08541 | S32: 507798.66 | T32: 6.9150685 | U32: 5-7yrs | V32: DE | W32: 900000000 | X32: 10
A33: XS3000561566 | C33: HOG 4 03/12/30 | D33: 1061000 | E33: HOG | F33: Harley-Davidson Financial Services Inc | G33: Consumer, Cyclical | H33: Leisure Time | I33: Baa3 | J33: BBB- | K33: BBB+ | L33: BBB- | M33: Senior Unsecured | N33: 3.6456711 | O33: Spread | P33: 102.52777 | Q33: 116.364 | R33: 3.32854 | S33: 1087819.6 | T33: 4.3506849 | U33: 3-5yrs | V33: US | W33: 610000000 | X33: 10
A34: XS2583741934 | B34: 459200LA7 | C34: IBM 3 3/8 02/06/27 | D34: 2000000 | E34: IBM | F34: International Business Machines Corp | G34: Technology | H34: Computers | I34: A3 | J34: A- | K34: A- | L34: A- | M34: Senior Unsecured | N34: 1.1086753 | O34: Spread | P34: 101.15517 | Q34: 40.187 | R34: 2.35377 | S34: 2023103.3 | T34: 1.2547945 | U34: 1-3yrs | V34: US | W34: 1000000000 | X34: 7
A35: XS3189697793 | C35: IDSLN 4 10/01/32 | D35: 1237000 | E35: IDSLN | F35: IDS Financing PLC | G35: Industrial | H35: Transportation | I35: N/A | J35: BBB- | K35: N/A | L35: BBB- | M35: Senior Unsecured | N35: 5.9002795 | O35: Spread | P35: 99.683797 | Q35: 165.874 | R35: 4.05224 | S35: 1233088.6 | T35: 6.909589 | U35: 5-7yrs | V35: GB | W35: 750000000 | X35: 10
A36: XS2123320033 | C36: JPM 0.389 02/24/28 | D36: 2000000 | E36: JPM | F36: JPMorgan Chase & Co | G36: Financial | H36: Banks | I36: A1 | J36: A | K36: AA- | L36: A+ | M36: Senior Unsecured | N36: 1.262809 | O36: Spread | P36: 97.30555 | Q36: 58.038 | R36: 2.52328 | S36: 1946111 | T36: 2.3041096 | U36: 1-3yrs | V36: US | W36: 1250000000 | X36: 5
A37: XS2905504671 | C37: KNOGR 3 09/30/29 | D37: 500000 | E37: KNOGR | F37: Knorr-Bremse AG | G37: Industrial | H37: Miscellaneous Manufactur | I37: A3 | J37: N/A | K37: N/A | L37: A- | M37: Senior Unsecured | N37: 3.3982509 | O37: Spread | P37: 100.59158 | Q37: 70.921 | R37: 2.82781 | S37: 502957.91 | T37: 3.9041096 | U37: 3-5yrs | V37: DE | W37: 600000000 | X37: 7
A38: FR0014013DU9 | C38: LAMON 4 3/8 10/20/35 | D38: 2000000 | E38: LAMON | F38: La Mondiale SAM | G38: Financial | H38: Insurance | I38: N/A | J38: BBB+ | K38: N/A | L38: BBB+ | M38: Subordinated LT2 | N38: 7.5979267 | O38: Spread | P38: 100.57064 | Q38: 164.3 | R38: 4.3017003 | S38: 2011412.7 | T38: 9.9616438 | U38: 7-10yrs | V38: FR | W38: 500000000 | X38: 8
A39: XS3214761473 | C39: MNDILN 3 3/8 05/23/31 | D39: 1155000 | E39: MNDILN | F39: Mondi Finance PLC | G39: Basic Materials | H39: Forest Products&Paper | I39: Baa1 | J39: BBB+ | K39: N/A | L39: BBB+ | M39: Senior Unsecured | N39: 4.961983 | O39: Spread | P39: 99.67159 | Q39: 119.383 | R39: 3.44343 | S39: 1151206.9 | T39: 5.5479452 | U39: 5-7yrs | V39: AT | W39: 550000000 | X39: 8
A40: DE000MHB67Q8 | C40: MUNHYP 3 3/8 04/11/35 | D40: 2000000 | E40: MUNHYP | F40: Muenchener Hypothekenbank eG | G40: Financial | H40: Banks | I40: A1 | J40: N/A | K40: N/A | L40: A+ | M40: Senior Unsecured | N40: 7.9175902 | O40: Spread | P40: 98.237446 | Q40: 98.54 | R40: 3.6005 | S40: 1964748.9 | T40: 9.4356164 | U40: 7-10yrs | V40: DE | W40: 500000000 | X40: 5
A41: XS3185372326 | C41: NESNVX 3 09/23/33 | D41: 2000000 | E41: NESNVX | F41: Nestle Finance International Ltd | G41: Consumer, Non-cyclical | H41: Food | I41: Aa3 | J41: AA- | K41: N/A | L41: AA- | M41: Senior Unsecured | N41: 6.8964556 | O41: Spread | P41: 99.746154 | Q41: 53.672 | R41: 3.03602 | S41: 1994923.1 | T41: 7.8876712 | U41: 7-10yrs | V41: US | W41: 600000000 | X41: 4
A42: XS1821883102 | C42: NFLX 3 5/8 05/15/27 | D42: 1951000 | E42: NFLX | F42: Netflix Inc | G42: Communications | H42: Internet | I42: A3 | J42: A | K42: N/A | L42: A- | M42: Senior Unsecured | N42: 1.453553 | O42: Spread | P42: 101.98156 | Q42: 34.82 | R42: 2.2926593 | S42: 1989660.1 | T42: 1.5232877 | U42: 1-3yrs | V42: US | W42: 1300000000 | X42: 7
A43: XS3066581664 | C43: NOMURA 3.459 05/28/30 | D43: 1657000 | E43: NOMURA | F43: Nomura Holdings Inc | G43: Financial | H43: Diversified Finan Serv | I43: Baa1 | J43: N/A | K43: A- | L43: BBB+ | M43: Senior Unsecured | N43: 4.1044625 | O43: Spread | P43: 101.39747 | Q43: 91.433 | R43: 3.12183 | S43: 1680156.1 | T43: 4.5616438 | U43: 3-5yrs | V43: JP | W43: 700000000 | X43: 8
...

Sheet USD JULI-ex EM proxy
A1: ISIN | B1: CUSIP | C1: Bond | D1: Notional | E1: Ticker | F1: Issuer | G1: Sector | H1: Group | I1: Moody | J1: S&P | K1: Fitch | L1: Rating | M1: Payment Rank | N1: Duration | O1: Quote Type | P1: JPM Price | Q1: JPM Spread | R1: JPM Yield | S1: JPM MV | T1: Years to Maturity | U1: Maturity Bucket | V1: Country | W1: Amount Outstanding | X1: Ordinal Rating | Y1: Notional EUR equiv | Z1: JPM MV USD | AA1: JPM Yield USD
A2: US00287YDW66 | B2: 00287YDW6 | C2: ABBV 5.4 03/15/54 | D2: 1518000 | E2: ABBV | F2: AbbVie Inc | G2: Consumer, Non-cyclical | H2: Pharmaceuticals | I2: A3 | J2: A- | K2: N/A | L2: A- | M2: Senior Unsecured | N2: 14.214947 | O2: Spread | P2: 98.445235 | Q2: 77.6364 | R2: =AA2+Overview!$C$59*100 -> 3.568464 | S2: =Z2*(1/Overview!$C$58) -> 1301514.3 | T2: 28.375342 | U2: 10yrs+ | V2: US | W2: 3000000000 | X2: 7 | Y2: =D2/Overview!$C$58 -> 1322069.3 | Z2: =D2*P2/100 -> 1494398.7 | AA2: 5.508464
A3: US03522AAJ97 | B3: 03522AAJ9 | C3: ABIBB 4.9 02/01/46 | D3: 1608000 | E3: ABIBB | F3: Anheuser-Busch Cos LLC / Anheuser-Busch InBev Worldwide Inc | G3: Consumer, Non-cyclical | H3: Beverages | I3: A3 | J3: A- | K3: WD | L3: A- | M3: Senior Unsecured | N3: 12.26743 | O3: Spread | P3: 93.148331 | Q3: 75.4932 | R3: =AA3+Overview!$C$59*100 -> 3.523032 | S3: =Z3*(1/Overview!$C$58) -> 1304498.5 | T3: 20.254795 | U3: 10yrs+ | V3: BE | W3: 8806284000 | X3: 7 | Y3: =D3/Overview!$C$58 -> 1400452.9 | Z3: =D3*P3/100 -> 1497825.2 | AA3: 5.463032
A4: US00774MAW55 | B4: 00774MAW5 | C4: AER 3 10/29/28 | D4: 1555000 | E4: AER | F4: AerCap Ireland Capital DAC / AerCap Global Aviation Trust | G4: Financial | H4: Diversified Finan Serv | I4: Baa1 | J4: BBB+ | K4: BBB+ | L4: BBB+ | M4: Senior Unsecured | N4: 2.8090513 | O4: Spread | P4: 96.399765 | Q4: 65.6065 | R4: =AA4+Overview!$C$59*100 -> 2.359665 | S4: =Z4*(1/Overview!$C$58) -> 1305535.9 | T4: 2.9835616 | U4: 1-3yrs | V4: IE | W4: 3750000000 | X4: 8 | Y4: =D4/Overview!$C$58 -> 1354293.7 | Z4: =D4*P4/100 -> 1499016.3 | AA4: 4.299665
A5: US031162DR88 | B5: 031162DR8 | C5: AMGN 5 1/4 03/02/33 | D5: 1452000 | E5: AMGN | F5: Amgen Inc | G5: Consumer, Non-cyclical | H5: Biotechnology | I5: Baa1 | J5: BBB+ | K5: BBB | L5: BBB+ | M5: Senior Unsecured | N5: 5.8279847 | O5: Spread | P5: 103.22221 | Q5: 55.7474 | R5: =AA5+Overview!$C$59*100 -> 2.768774 | S5: =Z5*(1/Overview!$C$58) -> 1305335.7 | T5: 7.3260274 | U5: 5-7yrs | V5: US | W5: 4250000000 | X5: 8 | Y5: =D5/Overview!$C$58 -> 1264588.1 | Z5: =D5*P5/100 -> 1498786.5 | AA5: 4.708774
A6: US11135FAQ46 | B6: 11135FAQ4 | C6: AVGO 4.15 11/15/30 | D6: 757000 | E6: AVGO | F6: Broadcom Inc | G6: Technology | H6: Semiconductors | I6: A3 | J6: A- | K6: BBB+ | L6: A- | M6: Senior Unsecured | N6: 4.3997488 | O6: Spread | P6: 99.088412 | Q6: 59.3599 | R6: =AA6+Overview!$C$59*100 -> 2.413699 | S6: =Z6*(1/Overview!$C$58) -> 653282.77 | T6: 5.030137 | U6: 3-5yrs | V6: US | W6: 1854642000 | X6: 7 | Y6: =D6/Overview!$C$58 -> 659292.81 | Z6: =D6*P6/100 -> 750099.28 | AA6: 4.353699
A7: US11135FBV22 | B7: 11135FBV2 | C7: AVGO 4.926 05/15/37 | D7: 756000 | E7: AVGO | F7: Broadcom Inc | G7: Technology | H7: Semiconductors | I7: A3 | J7: A- | K7: BBB+ | L7: A- | M7: Senior Unsecured | N7: 8.4926332 | O7: Spread | P7: 98.927812 | Q7: 89.8382 | R7: =AA7+Overview!$C$59*100 -> 3.109682 | S7: =Z7*(1/Overview!$C$58) -> 651362.36 | T7: 11.531507 | U7: 10yrs+ | V7: US | W7: 2500000000 | X7: 7 | Y7: =D7/Overview!$C$58 -> 658421.88 | Z7: =D7*P7/100 -> 747894.26 | AA7: 5.049682
A8: US025816CS64 | B8: 025816CS6 | C8: AXP 2.55 03/04/27 | D8: 1527000 | E8: AXP | F8: American Express Co | G8: Financial | H8: Diversified Finan Serv | I8: A2 | J8: A- | K8: A | L8: A | M8: Senior Unsecured | N8: 1.2835125 | O8: Spread | P8: 98.223011 | Q8: 30.1968 | R8: =AA8+Overview!$C$59*100 -> 1.9945127 | S8: =Z8*(1/Overview!$C$58) -> 1306275.4 | T8: 1.3260274 | U8: 1-3yrs | V8: US | W8: 1750000000 | X8: 6 | Y8: =D8/Overview!$C$58 -> 1329907.7 | Z8: =D8*P8/100 -> 1499865.4 | AA8: 3.9345127
A9: US097023CW33 | B9: 097023CW3 | C9: BA 5.805 05/01/50 | D9: 1511000 | E9: BA | F9: Boeing Co/The | G9: Industrial | H9: Aerospace/Defense | I9: Baa3 | J9: BBB- | K9: BBB- | L9: BBB- | M9: Senior Unsecured | N9: 12.904614 | O9: Spread | P9: 98.845865 | Q9: 116.2458 | R9: =AA9+Overview!$C$59*100 -> 3.954558 | S9: =Z9*(1/Overview!$C$58) -> 1300784.7 | T9: 24.50137 | U9: 10yrs+ | V9: US | W9: 5500000000 | X9: 10 | Y9: =D9/Overview!$C$58 -> 1315972.8 | Z9: =D9*P9/100 -> 1493561 | AA9: 5.894558
A10: US06051GHD43 | B10: 06051GHD4 | C10: BAC 3.419 12/20/28 | D10: 1523000 | E10: BAC | F10: Bank of America Corp | G10: Financial | H10: Banks | I10: A1 | J10: A- | K10: AA- | L10: A+ | M10: Senior Unsecured | N10: 1.9968568 | O10: Spread | P10: 98.447131 | Q10: 55.7704 | R10: =AA10+Overview!$C$59*100 -> 2.2497331 | S10: =Z10*(1/Overview!$C$58) -> 1305826.3 | T10: 3.1260274 | U10: 1-3yrs | V10: US | W10: 5989208000 | X10: 5 | Y10: =D10/Overview!$C$58 -> 1326424 | Z10: =D10*P10/100 -> 1499349.8 | AA10: 4.1897331
A11: US06738ECG89 | B11: 06738ECG8 | C11: BACR 6.224 05/09/34 | D11: 1398000 | E11: BACR | F11: Barclays PLC | G11: Financial | H11: Banks | I11: Baa1 | J11: BBB+ | K11: A | L11: BBB+ | M11: Senior Unsecured | N11: 5.8458452 | O11: Spread | P11: 108.4547 | Q11: 93.1709 | R11: =AA11+Overview!$C$59*100 -> 3.143009 | S11: =Z11*(1/Overview!$C$58) -> 1320498.8 | T11: 8.5123288 | U11: 7-10yrs | V11: GB | W11: 2000000000 | X11: 8 | Y11: =D11/Overview!$C$58 -> 1217557.9 | Z11: =D11*P11/100 -> 1516196.7 | AA11: 5.083009
A12: US110122EK02 | B12: 110122EK0 | C12: BMY 5.55 02/22/54 | D12: 1506000 | E12: BMY | F12: Bristol-Myers Squibb Co | G12: Consumer, Non-cyclical | H12: Pharmaceuticals | I12: A2 | J12: A | K12: N/A | L12: A | M12: Senior Unsecured | N12: 13.966293 | O12: Spread | P12: 99.058666 | Q12: 88.4045 | R12: =AA12+Overview!$C$59*100 -> 3.676145 | S12: =Z12*(1/Overview!$C$58) -> 1299271.5 | T12: 28.317808 | U12: 10yrs+ | V12: US | W12: 2750000000 | X12: 6 | Y12: =D12/Overview!$C$58 -> 1311618.2 | Z12: =D12*P12/100 -> 1491823.5 | AA12: 5.616145
A13: US09659W2P81 | B13: 09659W2P8 | C13: BNP 2.871 04/19/32 | D13: 1654000 | E13: BNP | F13: BNP Paribas SA | G13: Financial | H13: Banks | I13: Baa1 | J13: A- | K13: A+ | L13: A- | M13: Senior Unsecured | N13: 5.75 | O13: Spread | P13: 90.627 | Q13: 109.4911 | R13: =AA13+Overview!$C$59*100 -> 2.91 | S13: =Z13*(1/Overview!$C$58) -> 1305496.1 | T13: 6.4575342 | U13: 5-7yrs | V13: FR | W13: 2250000000 | X13: 7 | Y13: =D13/Overview!$C$58 -> 1440515.6 | Z13: =D13*P13/100 -> 1498970.6 | AA13: 4.85
... A65: US30231GBF81 | B65: 30231GBF8 | C65: XOM 4.227 03/19/40 | D65: 820000 | E65: XOM | F65: Exxon Mobil Corp | G65: Energy | H65: Oil&Gas | I65: Aa2 | J65: AA- | K65: N/A | L65: AA- | M65: Senior Unsecured | N65: 10.398407 | O65: Spread | P65: 91.347461 | Q65: 93.104 | R65: =AA65+Overview!$C$59*100 -> 3.14234 | S65: =Z65*(1/Overview!$C$58) -> 652368.21 | T65: 14.378082 | U65: 10yrs+ | V65: US | W65: 2000000000 | X65: 4 | Y65: =D65/Overview!$C$58 -> 714161.3 | Z65: =D65*P65/100 -> 749049.18 | AA65: 5.08234

Sheet Rating Map
A1: 1 | B1: AAA | C1: 1
A2: 2 | B2: AA+ | C2: 2
A3: 3 | B3: AA | C3: 3
A4: 4 | B4: AA- | C4: 4
A5: 5 | B5: A+ | C5: 5
A6: 6 | B6: A | C6: 6
A7: 7 | B7: A- | C7: 7
A8: 8 | B8: BBB+ | C8: 8
A9: 9 | B9: BBB | C9: 9
A10: 10 | B10: BBB- | C10: 10
A11: 11 | B11: BB+ | C11: 11
A12: 12 | B12: BB | C12: 12
... A27: 27 | B27: None | C27: 27
